<?xml version="1.0" ?>
<robot name="rakuda" xmlns:xacro="http://www.ros.org/wiki/xacro">

<!-- Variabile testa anche inseribile in file launch-->
<xacro:arg name="head_type" default="apollo"/>

<xacro:property name="head_type" value="$(arg head_type)"/>


<xacro:include filename="$(find rakuda_description)/urdf/gemini_335_336.urdf.xacro" />
<xacro:include filename="$(find rakuda_description)/urdf/materials.xacro" />
<xacro:include filename="$(find rakuda_description)/urdf/rakuda.ros2_control.xacro" />
<xacro:include filename="$(find rakuda_description)/urdf/rakuda.gazebo" />

<!-- Teste disponibili -->
<xacro:include filename="$(find rakuda_description)/urdf/head_apollo.urdf.xacro"/>
<xacro:include filename="$(find rakuda_description)/urdf/head_sciurus.urdf.xacro"/>


<!-- Scelta della testa da caricare -->
<xacro:if value="${head_type == 'apollo'}">
  <xacro:head_apollo parent_link="neck_yaw_link"/>
</xacro:if>

<xacro:if value="${head_type == 'sciurus'}">
  <xacro:head_sciurus parent_link="neck_yaw_link"/>
</xacro:if>


<!-- 'base_link'  to Gazebo 'world' 
<link name="world"/>

<joint name="base_link_to_world_joint" type="fixed">
  <parent link="world"/>
  <child link="base_link"/>
</joint>
-->

<!-- Main links -->

<link name="base_link">
  <visual>
    <origin xyz="0 0 0" rpy="0 0 0"/>
    <geometry>
      <mesh filename="file://$(find rakuda_description)/meshes/visual/base_link.stl" scale="0.001 0.001 0.001"/>
    </geometry>
    <material name="white"/>
  </visual>
  <collision>
    <origin xyz="0 0 0" rpy="0 0 0"/>
    <geometry>
      <mesh filename="file://$(find rakuda_description)/meshes/collision/base_link_collision.stl" scale="0.001 0.001 0.001"/>
    </geometry>
  </collision>
</link>

<link name="base_inertia_link">
  <inertial>
    <origin xyz="-0.020408922979267937 -4.8555006463835264e-05 0.05284203414197219" rpy="0 0 0"/>
    <mass value="1.1379124037846244"/>
    <inertia ixx="5787e-06" iyy="6743e-06" izz="3335e-06" ixy="-4e-06" iyz="-2e-06" ixz="-576e-06"/>
  </inertial>
</link>

<joint name="base_inertia_joint" type="fixed">
  <parent link="base_link"/>
  <child link="base_inertia_link"/>
  <origin xyz="0 0 0" rpy="0 0 0"/>
</joint>


<link name="waist_link">
  <inertial>
    <origin xyz="0.00015195021146941867 -2.820226960486473e-06 -0.004137928658236423" rpy="0 0 0"/>
    <mass value="0.04400005195575271"/>
    <inertia ixx="10e-06" iyy="13e-06" izz="17e-06" ixy="0" iyz="0" ixz="0"/>
  </inertial>
  <visual>
    <origin xyz="0.0 0.0 -0.302" rpy="0 0 0"/>
    <geometry>
      <mesh filename="file://$(find rakuda_description)/meshes/visual/waist_link.stl" scale="0.001 0.001 0.001"/>
    </geometry>
    <material name="white"/>
  </visual>
  <collision>
    <origin xyz="0.0 0.0 -0.302" rpy="0 0 0"/>
    <geometry>
      <mesh filename="file://$(find rakuda_description)/meshes/collision/waist_link_collision.stl" scale="0.001 0.001 0.001"/>
    </geometry>
  </collision>
</link>

<link name="torso_link">
  <inertial>
    <origin xyz="-0.005791332469439025 1.1532258378440722e-08 0.06653504643352193" rpy="0 0 0"/>
    <mass value="0.7540141547961345"/>
    <inertia ixx="1985e-06" iyy="909e-06" izz="1513e-06" ixy="0" iyz="0" ixz="-55e-06"/>
  </inertial>
  <visual>
    <origin xyz="-0.0 -0.0 -0.3085" rpy="0 0 0"/>
    <geometry>
      <mesh filename="file://$(find rakuda_description)/meshes/visual/torso_link.stl" scale="0.001 0.001 0.001"/>
    </geometry>
    <material name="white"/>
  </visual>
  <collision>
    <origin xyz="-0.0 -0.0 -0.3085" rpy="0 0 0"/>
    <geometry>
      <mesh filename="file://$(find rakuda_description)/meshes/collision/torso_link_collision.stl" scale="0.001 0.001 0.001"/>
    </geometry>
  </collision>
</link>

<link name="neck_yaw_link">
  <inertial>
    <origin xyz="2.8236692876973818e-15 -0.0003318177210791965 0.010126539608700469" rpy="0 0 0"/>
    <mass value="0.01399997346170466"/>
    <inertia ixx="5e-06" iyy="3e-06" izz="4e-06" ixy="0" iyz="0" ixz="0"/>
  </inertial>
  <visual>
    <origin xyz="-0.0 -0.0 -0.43405" rpy="0 0 0"/>
    <geometry>
      <mesh filename="file://$(find rakuda_description)/meshes/visual/neck_yaw_link.stl" scale="0.001 0.001 0.001"/>
    </geometry>
    <material name="white"/>
  </visual>
  <collision>
    <origin xyz="-0.0 -0.0 -0.43405" rpy="0 0 0"/>
    <geometry>
      <mesh filename="file://$(find rakuda_description)/meshes/collision/neck_yaw_link_collision.stl" scale="0.001 0.001 0.001"/>
    </geometry>
  </collision>
</link>


<!-- Chiama la macro che aggancia il ros control: Inserire il numero totale di Dynamixel -->
<xacro:property name="dof" value="17"/>
<xacro:rakuda_ros2_control_settings dof="${dof}"/>


<!-- Link braccia -->
<link name="l_link1">
  <inertial>
    <origin xyz="8.165392508629886e-05 0.017114007906281148 -0.01682274344663298" rpy="0 0 0"/>
    <mass value="0.07299177430140238"/>
    <inertia ixx="40e-06" iyy="51e-06" izz="57e-06" ixy="0" iyz="8e-06" ixz="0"/>
  </inertial>
  <visual>
    <origin xyz="-0.0 -0.0826 -0.3946" rpy="0 0 0"/>
    <geometry>
      <mesh filename="file://$(find rakuda_description)/meshes/visual/l_link1.stl" scale="0.001 0.001 0.001"/>
    </geometry>
    <material name="white"/>
  </visual>
  <collision>
    <origin xyz="-0.0 -0.0826 -0.3946" rpy="0 0 0"/>
    <geometry>
      <mesh filename="file://$(find rakuda_description)/meshes/collision/l_link1_collision.stl" scale="0.001 0.001 0.001"/>
    </geometry>
  </collision>
</link>

<link name="r_link1">
  <inertial>
    <origin xyz="7.710992934052517e-05 -0.017114009124667 -0.016822741627550486" rpy="0 0 0"/>
    <mass value="0.07299176592385347"/>
    <inertia ixx="40e-06" iyy="51e-06" izz="57e-06" ixy="0" iyz="-8e-06" ixz="0"/>
  </inertial>
  <visual>
    <origin xyz="-0.0 0.0826 -0.3946" rpy="0 0 0"/>
    <geometry>
      <mesh filename="file://$(find rakuda_description)/meshes/visual/r_link1.stl" scale="0.001 0.001 0.001"/>
    </geometry>
    <material name="white"/>
  </visual>
  <collision>
    <origin xyz="-0.0 0.0826 -0.3946" rpy="0 0 0"/>
    <geometry>
      <mesh filename="file://$(find rakuda_description)/meshes/collision/r_link1_collision.stl" scale="0.001 0.001 0.001"/>
    </geometry>
  </collision>
</link>

<link name="l_link2">
  <inertial>
    <origin xyz="2.482738387163369e-05 0.000396191411047242 -0.03040144548272805" rpy="0 0 0"/>
    <mass value="0.2900252815965671"/>
    <inertia ixx="279e-06" iyy="303e-06" izz="102e-06" ixy="-1e-06" iyz="-2e-06" ixz="-7e-06"/>
  </inertial>
  <visual>
    <origin xyz="-0.0 -0.1236 -0.3706" rpy="0 0 0"/>
    <geometry>
      <mesh filename="file://$(find rakuda_description)/meshes/visual/l_link2.stl" scale="0.001 0.001 0.001"/>
    </geometry>
    <material name="white"/>
  </visual>
  <collision>
    <origin xyz="-0.0 -0.1236 -0.3706" rpy="0 0 0"/>
    <geometry>
      <mesh filename="file://$(find rakuda_description)/meshes/collision/l_link2_collision.stl" scale="0.001 0.001 0.001"/>
    </geometry>
  </collision>
</link>

<link name="r_link2">
  <inertial>
    <origin xyz="2.4825375508370262e-05 -0.0003961910521785711 -0.030401438771675282" rpy="0 0 0"/>
    <mass value="0.2900253610511383"/>
    <inertia ixx="0.000279" iyy="0.000303" izz="0.000102" ixy="1e-06" iyz="2e-06" ixz="-7e-06"/>
  </inertial>
  <visual>
    <origin xyz="-0.0 0.1236 -0.3706" rpy="0 0 0"/>
    <geometry>
      <mesh filename="file://$(find rakuda_description)/meshes/visual/r_link2.stl" scale="0.001 0.001 0.001"/>
    </geometry>
    <material name="white"/>
  </visual>
  <collision>
    <origin xyz="-0.0 0.1236 -0.3706" rpy="0 0 0"/>
    <geometry>
      <mesh filename="file://$(find rakuda_description)/meshes/collision/r_link2_collision.stl" scale="0.001 0.001 0.001"/>
    </geometry>
  </collision>
</link>

<link name="l_link3">
  <inertial>
    <origin xyz="0.012816931345662554 0.0004977011098152018 -0.019558162431457693" rpy="0 0 0"/>
    <mass value="0.10799652996016351"/>
    <inertia ixx="25e-06" iyy="43e-06" izz="40e-06" ixy="0" iyz="0" ixz="1e-06"/>
  </inertial>
  <visual>
    <origin xyz="-0.012 -0.1236 -0.2884" rpy="0 0 0"/>
    <geometry>
      <mesh filename="file://$(find rakuda_description)/meshes/visual/l_link3.stl" scale="0.001 0.001 0.001"/>
    </geometry>
    <material name="white"/>
  </visual>
  <collision>
    <origin xyz="-0.012 -0.1236 -0.2884" rpy="0 0 0"/>
    <geometry>
      <mesh filename="file://$(find rakuda_description)/meshes/collision/l_link3_collision.stl" scale="0.001 0.001 0.001"/>
    </geometry>
  </collision>
</link>

<link name="r_link3">
  <inertial>
    <origin xyz="0.01281693134567282 -0.0004977011098376977 -0.019558162431519532" rpy="0 0 0"/>
    <mass value="0.10799652996026934"/>
    <inertia ixx="25e-06" iyy="43e-06" izz="40e-06" ixy="0" iyz="0" ixz="1e-06"/>
  </inertial>
  <visual>
    <origin xyz="-0.012 0.1236 -0.2884" rpy="0 0 0"/>
    <geometry>
      <mesh filename="file://$(find rakuda_description)/meshes/visual/r_link3.stl" scale="0.001 0.001 0.001"/>
    </geometry>
    <material name="white"/>
  </visual>
  <collision>
    <origin xyz="-0.012 0.1236 -0.2884" rpy="0 0 0"/>
    <geometry>
      <mesh filename="file://$(find rakuda_description)/meshes/collision/r_link3_collision.stl" scale="0.001 0.001 0.001"/>
    </geometry>
  </collision>
</link>

<link name="l_link4">
  <inertial>
    <origin xyz="-0.013529205112779118 0.001169548907603693 -0.04421637055831898" rpy="0 0 0"/>
    <mass value="0.10699509679197633"/>
    <inertia ixx="30e-06" iyy="43e-06" izz="36e-06" ixy="1e-06" iyz="0" ixz="-2e-06"/>
  </inertial>
  <visual>
    <origin xyz="-0.036 -0.1236 -0.27035" rpy="0 0 0"/>
    <geometry>
      <mesh filename="file://$(find rakuda_description)/meshes/visual/l_link4.stl" scale="0.001 0.001 0.001"/>
    </geometry>
    <material name="white"/>
  </visual>
  <collision>
    <origin xyz="-0.036 -0.1236 -0.27035" rpy="0 0 0"/>
    <geometry>
      <mesh filename="file://$(find rakuda_description)/meshes/collision/l_link4_collision.stl" scale="0.001 0.001 0.001"/>
    </geometry>
  </collision>
</link>

<link name="r_link4">
  <inertial>
    <origin xyz="-0.013529205589267821 -0.0011695493323802958 -0.04421637085671126" rpy="0 0 0"/>
    <mass value="0.10699509934326328"/>
    <inertia ixx="30e-06" iyy="43e-06" izz="36e-06" ixy="-1e-06" iyz="0" ixz="-2e-06"/>
  </inertial>
  <visual>
    <origin xyz="-0.036 0.1236 -0.27035" rpy="0 0 0"/>
    <geometry>
      <mesh filename="file://$(find rakuda_description)/meshes/visual/r_link4.stl" scale="0.001 0.001 0.001"/>
    </geometry>
    <material name="white"/>
  </visual>
  <collision>
    <origin xyz="-0.036 0.1236 -0.27035" rpy="0 0 0"/>
    <geometry>
      <mesh filename="file://$(find rakuda_description)/meshes/collision/r_link4_collision.stl" scale="0.001 0.001 0.001"/>
    </geometry>
  </collision>
</link>

<link name="l_link5">
  <inertial>
    <origin xyz="-0.00010745262237027431 0.0004983218880769968 -0.02809682280934908" rpy="0 0 0"/>
    <mass value="0.10899653712889695"/>
    <inertia ixx="40e-06" iyy="44e-06" izz="26e-06" ixy="0" iyz="0" ixz="0"/>
  </inertial>
  <visual>
    <origin xyz="-0.036 -0.1236 -0.2049" rpy="0 0 0"/>
    <geometry>
      <mesh filename="file://$(find rakuda_description)/meshes/visual/l_link5.stl" scale="0.001 0.001 0.001"/>
    </geometry>
    <material name="white"/>
  </visual>
  <collision>
    <origin xyz="-0.036 -0.1236 -0.2049" rpy="0 0 0"/>
    <geometry>
      <mesh filename="file://$(find rakuda_description)/meshes/collision/l_link5_collision.stl" scale="0.001 0.001 0.001"/>
    </geometry>
  </collision>
</link>

<link name="r_link5">
  <inertial>
    <origin xyz="-0.00010749374651377458 -0.00049827898943898 -0.02809678801928564" rpy="0 0 0"/>
    <mass value="0.10899673027569862"/>
    <inertia ixx="40e-06" iyy="44e-06" izz="26e-06" ixy="0" iyz="0" ixz="0"/>
  </inertial>
  <visual>
    <origin xyz="-0.036 0.1236 -0.2049" rpy="0 0 0"/>
    <geometry>
      <mesh filename="file://$(find rakuda_description)/meshes/visual/r_link5.stl" scale="0.001 0.001 0.001"/>
    </geometry>
    <material name="white"/>
  </visual>
  <collision>
    <origin xyz="-0.036 0.1236 -0.2049" rpy="0 0 0"/>
    <geometry>
      <mesh filename="file://$(find rakuda_description)/meshes/collision/r_link5_collision.stl" scale="0.001 0.001 0.001"/>
    </geometry>
  </collision>
</link>

<link name="r_link6">
  <inertial>
    <origin xyz="0.0004978784895699889 -0.003188942119494928 -0.03994743914308038" rpy="0 0 0"/>
    <mass value="0.07399870180333049"/>
    <inertia ixx="23e-06" iyy="17e-06" izz="22e-06" ixy="0" iyz="0" ixz="0"/>
  </inertial>
  <visual>
    <origin xyz="-0.036 0.1236 -0.16585" rpy="0 0 0"/>
    <geometry>
      <mesh filename="file://$(find rakuda_description)/meshes/visual/r_link6.stl" scale="0.001 0.001 0.001"/>
    </geometry>
    <material name="white"/>
  </visual>
  <collision>
    <origin xyz="-0.036 0.1236 -0.16585" rpy="0 0 0"/>
    <geometry>
      <mesh filename="file://$(find rakuda_description)/meshes/collision/r_link6_collision.stl" scale="0.001 0.001 0.001"/>
    </geometry>
  </collision>
</link>

<link name="l_link6">
  <inertial>
    <origin xyz="0.000497878489597231 0.00318894211964936 -0.03994743914314852" rpy="0 0 0"/>
    <mass value="0.07399870180299768"/>
    <inertia ixx="23e-06" iyy="17e-06" izz="22e-06" ixy="0" iyz="0" ixz="0"/>
  </inertial>
  <visual>
    <origin xyz="-0.036 -0.1236 -0.16585" rpy="0 0 0"/>
    <geometry>
      <mesh filename="file://$(find rakuda_description)/meshes/visual/l_link6.stl" scale="0.001 0.001 0.001"/>
    </geometry>
    <material name="white"/>
  </visual>
  <collision>
    <origin xyz="-0.036 -0.1236 -0.16585" rpy="0 0 0"/>
    <geometry>
      <mesh filename="file://$(find rakuda_description)/meshes/collision/l_link6_collision.stl" scale="0.001 0.001 0.001"/>
    </geometry>
  </collision>
</link>

<link name="r_gripper_a">
  <inertial>
    <origin xyz="-8.852479904033345e-05 -0.003089211052713342 -0.02999149965192692" rpy="0 0 0"/>
    <mass value="0.017998423512260126"/>
    <inertia ixx="6e-06" iyy="10e-06" izz="5e-06" ixy="0" iyz="0" ixz="0"/>
  </inertial>
  <visual>
    <origin xyz="-0.036 0.1396 -0.1236" rpy="0 0 0"/>
    <geometry>
      <mesh filename="file://$(find rakuda_description)/meshes/visual/r_gripper_a.stl" scale="0.001 0.001 0.001"/>
    </geometry>
    <material name="white"/>
  </visual>
  <collision>
    <origin xyz="-0.036 0.1396 -0.1236" rpy="0 0 0"/>
    <geometry>
      <mesh filename="file://$(find rakuda_description)/meshes/collision/r_gripper_a_collision.stl" scale="0.001 0.001 0.001"/>
    </geometry>
  </collision>
</link>

<link name="r_gripper_b">
  <inertial>
    <origin xyz="-8.852479904033345e-05 0.003104658168288782 -0.030279426009768864" rpy="0 0 0"/>
    <mass value="0.018999892317782645"/>
    <inertia ixx="6e-06" iyy="10e-06" izz="5e-06" ixy="0" iyz="0" ixz="0"/>
  </inertial>
  <visual>
    <origin xyz="-0.036 0.1156 -0.12355" rpy="0 0 0"/>
    <geometry>
      <mesh filename="file://$(find rakuda_description)/meshes/visual/r_gripper_b.stl" scale="0.001 0.001 0.001"/>
    </geometry>
    <material name="white"/>
  </visual>
  <collision>
    <origin xyz="-0.036 0.1156 -0.12355" rpy="0 0 0"/>
    <geometry>
      <mesh filename="file://$(find rakuda_description)/meshes/collision/r_gripper_b_collision.stl" scale="0.001 0.001 0.001"/>
    </geometry>
  </collision>
</link>

<link name="l_gripper_a">
  <inertial>
    <origin xyz="-8.920360655783471e-05 0.003089714518583392 -0.029990508331487045" rpy="0 0 0"/>
    <mass value="0.017997801931831644"/>
    <inertia ixx="6e-06" iyy="10e-06" izz="5e-06" ixy="0" iyz="0" ixz="0"/>
  </inertial>
  <visual>
    <origin xyz="-0.036 -0.1396 -0.1236" rpy="0 0 0"/>
    <geometry>
      <mesh filename="file://$(find rakuda_description)/meshes/visual/l_gripper_a.stl" scale="0.001 0.001 0.001"/>
    </geometry>
    <material name="white"/>
  </visual>
  <collision>
    <origin xyz="-0.036 -0.1396 -0.1236" rpy="0 0 0"/>
    <geometry>
      <mesh filename="file://$(find rakuda_description)/meshes/collision/l_gripper_a_collision.stl" scale="0.001 0.001 0.001"/>
    </geometry>
  </collision>
</link>

<link name="l_gripper_b">
  <inertial>
    <origin xyz="-8.920360655783471e-05 -0.0031035251440137968 -0.030280490115251982" rpy="0 0 0"/>
    <mass value="0.019000550359800868"/>
    <inertia ixx="6e-06" iyy="10e-06" izz="5e-06" ixy="0" iyz="0" ixz="0"/>
  </inertial>
  <visual>
    <origin xyz="-0.036 -0.1156 -0.12355" rpy="0 0 0"/>
    <geometry>
      <mesh filename="file://$(find rakuda_description)/meshes/visual/l_gripper_b.stl" scale="0.001 0.001 0.001"/>
    </geometry>
    <material name="white"/>
  </visual>
  <collision>
    <origin xyz="-0.036 -0.1156 -0.12355" rpy="0 0 0"/>
    <geometry>
      <mesh filename="file://$(find rakuda_description)/meshes/collision/l_gripper_b_collision.stl" scale="0.001 0.001 0.001"/>
    </geometry>
  </collision>
</link>


<!-- Joints -->

<joint name="base_waist_joint" type="fixed">
  <origin xyz="0.0 0.0 0.306" rpy="0 0 0"/>
  <parent link="base_link"/>
  <child link="waist_link"/>
</joint>

<joint name="waist_yaw_joint" type="revolute">
  <origin xyz="0.0 0.0 0.0065" rpy="0 0 0"/>
  <parent link="waist_link"/>
  <child link="torso_link"/>
  <axis xyz="0.0 0.0 1.0"/>
  <limit upper="1.396263" lower="-1.396263" effort="100" velocity="100"/>
  <dynamics damping="1.0e-6" friction="0.8"/>
</joint>

<joint name="neck_yaw_joint" type="revolute">
  <origin xyz="0.0 0.0 0.12555" rpy="0 0 0"/>
  <parent link="torso_link"/>
  <child link="neck_yaw_link"/>
  <axis xyz="0.0 0.0 1.0"/>
  <!-- Sciurus17 limit upper="1.22173" lower="-1.22173" effort="100" velocity="100"/ -->
  <limit upper="0.660" lower="-0.660" effort="100" velocity="100"/>
  <dynamics damping="1.0e-6" friction="0.8"/>
</joint>

<joint name="l_arm_joint1" type="revolute">
  <origin xyz="0.0 0.0826 0.0861" rpy="0 0 0"/>
  <parent link="torso_link"/>
  <child link="l_link1"/>
  <axis xyz="0.0 1.0 0.0"/>
  <limit upper="0.0" lower="-2.96706" effort="100" velocity="100"/>
  <dynamics damping="1.0e-6" friction="0.8"/>
</joint>

<joint name="r_arm_joint1" type="revolute">
  <origin xyz="0.0 -0.0826 0.0861" rpy="0 0 0"/>
  <parent link="torso_link"/>
  <child link="r_link1"/>
  <axis xyz="0.0 -1.0 0.0"/>
  <limit upper="2.96706" lower="0.0" effort="100" velocity="100"/>
  <dynamics damping="1.0e-6" friction="0.8"/>
</joint>

<joint name="l_arm_joint2" type="revolute">
  <origin xyz="0.0 0.041 -0.024" rpy="0 0 0"/>
  <parent link="l_link1"/>
  <child link="l_link2"/>
  <axis xyz="1.0 0.0 0.0"/>
  <limit upper="1.570796" lower="-0.0" effort="100" velocity="100"/>
  <dynamics damping="1.0e-6" friction="0.8"/>
</joint>

<joint name="r_arm_joint2" type="revolute">
  <origin xyz="0.0 -0.041 -0.024" rpy="0 0 0"/>
  <parent link="r_link1"/>
  <child link="r_link2"/>
  <axis xyz="1.0 0.0 0.0"/>
  <limit upper="0.0" lower="-1.570796" effort="100" velocity="100"/>
  <dynamics damping="1.0e-6" friction="0.8"/>
</joint>

<joint name="l_arm_joint3" type="revolute">
  <origin xyz="0.012 0.0 -0.0822" rpy="0 0 0"/>
  <parent link="l_link2"/>
  <child link="l_link3"/>
  <axis xyz="0.0 0.0 -1.0"/>
  <limit upper="1.396263" lower="-1.396263" effort="100" velocity="100"/>
  <dynamics damping="1.0e-6" friction="0.8"/>
</joint>

<joint name="r_arm_joint3" type="revolute">
  <origin xyz="0.012 0.0 -0.0822" rpy="0 0 0"/>
  <parent link="r_link2"/>
  <child link="r_link3"/>
  <axis xyz="0.0 0.0 -1.0"/>
  <limit upper="1.396263" lower="-1.396263" effort="100" velocity="100"/>
  <dynamics damping="1.0e-6" friction="0.8"/>
</joint>

<joint name="l_arm_joint4" type="revolute">
  <origin xyz="0.024 0.0 -0.01805" rpy="0 0 0"/>
  <parent link="l_link3"/>
  <child link="l_link4"/>
  <axis xyz="0.0 1.0 0.0"/>
  <limit upper="0.174533" lower="-2.356194" effort="100" velocity="100"/>
  <dynamics damping="1.0e-6" friction="0.8"/>
</joint>

<joint name="r_arm_joint4" type="revolute">
  <origin xyz="0.024 0.0 -0.01805" rpy="0 0 0"/>
  <parent link="r_link3"/>
  <child link="r_link4"/>
  <axis xyz="0.0 -1.0 0.0"/>
  <limit upper="2.356194" lower="-0.174533" effort="100" velocity="100"/>
  <dynamics damping="1.0e-6" friction="0.8"/>
</joint>

<joint name="l_arm_joint5" type="revolute">
  <origin xyz="0.0 0.0 -0.06545" rpy="0 0 0"/>
  <parent link="l_link4"/>
  <child link="l_link5"/>
  <axis xyz="0.0 0.0 -1.0"/>
  <limit upper="1.570796" lower="-1.570796" effort="100" velocity="100"/>
  <dynamics damping="1.0e-6" friction="0.8"/>
</joint>

<joint name="r_arm_joint5" type="revolute">
  <origin xyz="0.0 0.0 -0.06545" rpy="0 0 0"/>
  <parent link="r_link4"/>
  <child link="r_link5"/>
  <axis xyz="0.0 0.0 -1.0"/>
  <limit upper="1.570796" lower="-1.570796" effort="100" velocity="100"/>
  <dynamics damping="1.0e-6" friction="0.8"/>
</joint>

<joint name="r_arm_joint6" type="revolute">
  <origin xyz="0.0 0.0 -0.03905" rpy="0 0 0"/>
  <parent link="r_link5"/>
  <child link="r_link6"/>
  <axis xyz="0.0 -1.0 0.0"/>
  <limit upper="1.396263" lower="-1.396263" effort="100" velocity="100"/>
  <dynamics damping="1.0e-6" friction="0.8"/>
</joint>

<joint name="l_arm_joint6" type="revolute">
  <origin xyz="0.0 0.0 -0.03905" rpy="0 0 0"/>
  <parent link="l_link5"/>
  <child link="l_link6"/>
  <axis xyz="0.0 1.0 0.0"/>
  <limit upper="1.396263" lower="-1.396263" effort="100" velocity="100"/>
  <dynamics damping="1.0e-6" friction="0.8"/>
</joint>

<joint name="r_gripper_joint" type="revolute">
  <origin xyz="0.0 -0.016 -0.04225" rpy="0 0 0"/>
  <parent link="r_link6"/>
  <child link="r_gripper_a"/>
  <axis xyz="1.0 0.0 0.0"/>
  <limit upper="0.0" lower="-1.22173" effort="100" velocity="100"/>
  <dynamics damping="1.0e-6" friction="0.8"/>
</joint>

<joint name="r_gripper_mimic_joint" type="revolute">
  <origin xyz="0.0 0.008 -0.0423" rpy="0 0 0"/>
  <limit lower="-1.0" upper="0.01" effort="10" velocity="1.0"/>
  <parent link="r_link6"/>
  <child link="r_gripper_b"/>
  <axis xyz="1.0 0.0 0.0"/>
  <mimic joint="r_gripper_joint" multiplier="-1.0" offset="0.0"/>
</joint>

<joint name="l_gripper_joint" type="revolute">
  <origin xyz="0.0 0.016 -0.04225" rpy="0 0 0"/>
  <parent link="l_link6"/>
  <child link="l_gripper_a"/>
  <axis xyz="1.0 0.0 0.0"/>
  <limit upper="1.22173" lower="0.0" effort="100" velocity="100"/>
  <dynamics damping="1.0e-6" friction="0.8"/>
</joint>

<joint name="l_gripper_mimic_joint" type="revolute">
  <origin xyz="0.0 -0.008 -0.0423" rpy="0 0 0"/>
  <limit lower="-0.01" upper="1.0" effort="10" velocity="1.0"/>
  <parent link="l_link6"/>
  <child link="l_gripper_b"/>
  <axis xyz="1.0 0.0 0.0"/>
  <mimic joint="l_gripper_joint" multiplier="-1.0" offset="0.0"/>
</joint>

</robot>
