<?xml version="1.0" ?>
<!-- =================================================================================== -->
<!-- |    This document was autogenerated by xacro from /home/andrea/ros2_ws/install/rakuda_description/share/rakuda_description/urdf/rakuda.urdf.xacro | -->
<!-- |    EDITING THIS FILE BY HAND IS NOT RECOMMENDED                                 | -->
<!-- =================================================================================== -->
<robot name="rakuda">
  <material name="silver">
    <color rgba="0.7 0.7 0.7 1.0"/>
  </material>
  <material name="white">
    <color rgba="0.95 0.95 0.95 1.0"/>
  </material>
  <link name="neck_pitch_link">
    <inertial>
      <origin rpy="0 0 0" xyz="0.008396864265162956 -0.00019864066295206934 0.06883747797830841"/>
      <mass value="0.42095197205408197"/>
      <inertia ixx="4.708852" ixy="0.006132" ixz="0.094646" iyy="12.832797" iyz="-0.007571" izz="8.86896"/>
    </inertial>
    <visual>
      <origin rpy="0 0 0" xyz="0.0 -0.0001 -0.4606"/>
      <geometry>
        <mesh filename="file:///home/andrea/ros2_ws/install/rakuda_description/share/rakuda_description/meshes/visual/neck_pitch_link_ap.stl" scale="0.001 0.001 0.001"/>
      </geometry>
      <material name="white"/>
    </visual>
    <collision>
      <origin rpy="0 0 0" xyz="0.0 -0.0001 -0.4606"/>
      <geometry>
        <mesh filename="file:///home/andrea/ros2_ws/install/rakuda_description/share/rakuda_description/meshes/collision/neck_pitch_link_ap_collision.stl" scale="0.001 0.001 0.001"/>
      </geometry>
    </collision>
  </link>
  <joint name="neck_pitch_joint" type="revolute">
    <origin rpy="0 0 0" xyz="-0.0 0.0001 0.02655"/>
    <parent link="neck_yaw_link"/>
    <child link="neck_pitch_link"/>
    <axis xyz="0.0 -1.0 0.0"/>
    <limit effort="100" lower="-0.530" upper="0.5235" velocity="100"/>
    <dynamics damping="1.0e-6" friction="0.8"/>
  </joint>
  <link name="camera_link">
    <inertial>
      <origin rpy="0 0 0" xyz="0.00277269933215555 -1.06084680351007E-05 0.012801025085723"/>
      <mass value="0.0186143499064346"/>
      <inertia ixx="1.38922229644605E-05" ixy="-4.74617876641156E-09" ixz="1.99175628166615E-08" iyy="1.70686808598814E-06" iyz="-7.18717290327325E-09" izz="1.31766831843134E-05"/>
    </inertial>
    <visual>
      <origin rpy="0 0 0" xyz="0 0 0"/>
      <geometry>
        <mesh filename="package://orbbec_description/meshes/gemini335_336/camera_link.STL"/>
      </geometry>
      <material name="">
        <color rgba="0.01 0.01 0.01 1"/>
      </material>
    </visual>
    <collision>
      <origin rpy="0 0 0" xyz="0 0 0"/>
    </collision>
  </link>
  <link name="camera_left_ir_frame">
    <inertial>
      <origin rpy="0 0 0" xyz="-0.00158020887627678 -1.52683853303637E-08 -1.4860800305164E-07"/>
      <mass value="0.000453168790516429"/>
      <inertia ixx="4.34108781911687E-09" ixy="-3.69655517007001E-13" ixz="-1.45486421873185E-13" iyy="4.84012226840139E-09" iyz="1.92888940614786E-14" izz="4.84044260907388E-09"/>
    </inertial>
    <visual>
      <origin rpy="0 0 0" xyz="0 0 0"/>
      <geometry>
        <mesh filename="package://orbbec_description/meshes/gemini335_336/camera_left_ir_frame.STL"/>
      </geometry>
      <material name="">
        <color rgba="0.501960784313725 0.250980392156863 0.250980392156863 1"/>
      </material>
    </visual>
    <collision>
      <origin rpy="0 0 0" xyz="0 0 0"/>
    </collision>
  </link>
  <joint name="camera_left_ir_joint" type="fixed">
    <origin rpy="0 0 0" xyz="0.01587 -0.025 0.0125"/>
    <parent link="camera_link"/>
    <child link="camera_left_ir_frame"/>
  </joint>
  <link name="camera_left_ir_optical_frame">
    <inertial>
      <origin rpy="0 0 0" xyz="1.52683853338331E-08 1.48608003051636E-07 -0.00158020887627678"/>
      <mass value="0.000453168790516429"/>
      <inertia ixx="4.84012226840139E-09" ixy="1.92888940614797E-14" ixz="3.69655517006993E-13" iyy="4.84044260907388E-09" iyz="1.45486421873192E-13" izz="4.34108781911687E-09"/>
    </inertial>
    <visual>
      <origin rpy="0 0 0" xyz="0 0 0"/>
      <geometry>
        <mesh filename="package://orbbec_description/meshes/gemini335_336/camera_left_ir_optical_frame.STL"/>
      </geometry>
      <material name="">
        <color rgba="0.501960784313725 0.250980392156863 0.250980392156863 1"/>
      </material>
    </visual>
    <collision>
      <origin rpy="0 0 0" xyz="0 0 0"/>
    </collision>
  </link>
  <joint name="camera_left_ir_optical_joint" type="fixed">
    <origin rpy="-1.5707963267949 0 -1.5707963267949" xyz="0.01587 -0.025 0.0125"/>
    <parent link="camera_link"/>
    <child link="camera_left_ir_optical_frame"/>
  </joint>
  <link name="camera_right_ir_frame">
    <inertial>
      <origin rpy="0 0 0" xyz="-0.00158020887627678 -1.52683853303637E-08 -1.48608003050581E-07"/>
      <mass value="0.000453168790516429"/>
      <inertia ixx="4.34108781911687E-09" ixy="-3.69655517007898E-13" ixz="-1.45486421873762E-13" iyy="4.84012226840139E-09" iyz="1.92888940594506E-14" izz="4.84044260907389E-09"/>
    </inertial>
    <visual>
      <origin rpy="0 0 0" xyz="0 0 0"/>
      <geometry>
        <mesh filename="package://orbbec_description/meshes/gemini335_336/camera_right_ir_frame.STL"/>
      </geometry>
      <material name="">
        <color rgba="0.501960784313725 0.250980392156863 0.250980392156863 1"/>
      </material>
    </visual>
    <collision>
      <origin rpy="0 0 0" xyz="0 0 0"/>
    </collision>
  </link>
  <joint name="camera_right_ir_joint" type="fixed">
    <origin rpy="0 0 0" xyz="0.01587 0.025 0.0125"/>
    <parent link="camera_link"/>
    <child link="camera_right_ir_frame"/>
  </joint>
  <link name="camera_right_ir_optical_frame">
    <inertial>
      <origin rpy="0 0 0" xyz="1.52683853268942E-08 1.4860800305058E-07 -0.00158020887627678"/>
      <mass value="0.000453168790516429"/>
      <inertia ixx="4.84012226840139E-09" ixy="1.92888940594538E-14" ixz="3.69655517007897E-13" iyy="4.84044260907389E-09" iyz="1.45486421873764E-13" izz="4.34108781911687E-09"/>
    </inertial>
    <visual>
      <origin rpy="0 0 0" xyz="0 0 0"/>
      <geometry>
        <mesh filename="package://orbbec_description/meshes/gemini335_336/camera_right_ir_optical_frame.STL"/>
      </geometry>
      <material name="">
        <color rgba="0.501960784313725 0.250980392156863 0.250980392156863 1"/>
      </material>
    </visual>
    <collision>
      <origin rpy="0 0 0" xyz="0 0 0"/>
    </collision>
  </link>
  <joint name="camera_right_ir_optical_joint" type="fixed">
    <origin rpy="-1.5707963267949 0 -1.5707963267949" xyz="0.01587 0.025 0.0125"/>
    <parent link="camera_link"/>
    <child link="camera_right_ir_optical_frame"/>
  </joint>
  <link name="camera_color_frame">
    <inertial>
      <origin rpy="0 0 0" xyz="-0.00177079701156752 -2.20101367029782E-07 2.09893364599916E-07"/>
      <mass value="0.000139779365329478"/>
      <inertia ixx="6.69130695410276E-10" ixy="-1.53742421247628E-13" ixz="-2.28137695085953E-14" iyy="6.11277085561398E-10" iyz="4.18921196289284E-14" izz="6.11078036871936E-10"/>
    </inertial>
    <visual>
      <origin rpy="0 0 0" xyz="0 0 0"/>
      <geometry>
        <mesh filename="package://orbbec_description/meshes/gemini335_336/camera_color_frame.STL"/>
      </geometry>
      <material name="">
        <color rgba="0.501960784313725 0.250980392156863 0.250980392156863 1"/>
      </material>
    </visual>
    <collision>
      <origin rpy="0 0 0" xyz="0 0 0"/>
    </collision>
  </link>
  <joint name="camera_color_joint" type="fixed">
    <origin rpy="0 0 0" xyz="0.017533 0.010995 0.012505"/>
    <parent link="camera_link"/>
    <child link="camera_color_frame"/>
  </joint>
  <link name="camera_color_optical_frame">
    <inertial>
      <origin rpy="0 0 0" xyz="2.20101367029782E-07 -2.09893364599916E-07 -0.00177079701156752"/>
      <mass value="0.000139779365329478"/>
      <inertia ixx="6.11277085561398E-10" ixy="4.18921196289284E-14" ixz="1.53742421247628E-13" iyy="6.11078036871936E-10" iyz="2.28137695085953E-14" izz="6.69130695410276E-10"/>
    </inertial>
    <visual>
      <origin rpy="0 0 0" xyz="0 0 0"/>
      <geometry>
        <mesh filename="package://orbbec_description/meshes/gemini335_336/camera_color_optical_frame.STL"/>
      </geometry>
      <material name="">
        <color rgba="0.501960784313725 0.250980392156863 0.250980392156863 1"/>
      </material>
    </visual>
    <collision>
      <origin rpy="0 0 0" xyz="0 0 0"/>
    </collision>
  </link>
  <joint name="camera_color_optical_joint" type="fixed">
    <origin rpy="-1.5707963267949 0 -1.5707963267949" xyz="0.017533 0.010995 0.012505"/>
    <parent link="camera_link"/>
    <child link="camera_color_optical_frame"/>
  </joint>
  <link name="camera_depth_frame">
    <inertial>
      <origin rpy="0 0 0" xyz="-0.00158020887627678 -1.52683853338331E-08 -1.48608003051662E-07"/>
      <mass value="0.000453168790516429"/>
      <inertia ixx="4.34108781911687E-09" ixy="-3.69655517006982E-13" ixz="-1.45486421873185E-13" iyy="4.84012226840139E-09" iyz="1.92888940614707E-14" izz="4.84044260907388E-09"/>
    </inertial>
    <visual>
      <origin rpy="0 0 0" xyz="0 0 0"/>
      <geometry>
        <mesh filename="package://orbbec_description/meshes/gemini335_336/camera_depth_frame.STL"/>
      </geometry>
      <material name="">
        <color rgba="0.501960784313725 0.250980392156863 0.250980392156863 1"/>
      </material>
    </visual>
    <collision>
      <origin rpy="0 0 0" xyz="0 0 0"/>
    </collision>
  </link>
  <joint name="camera_depth_joint" type="fixed">
    <origin rpy="0 0 0" xyz="0.01587 -0.025 0.0125"/>
    <parent link="camera_link"/>
    <child link="camera_depth_frame"/>
  </joint>
  <link name="camera_depth_optical_frame">
    <inertial>
      <origin rpy="0 0 0" xyz="1.52683853338331E-08 1.4860800305165E-07 -0.00158020887627678"/>
      <mass value="0.000453168790516429"/>
      <inertia ixx="4.84012226840139E-09" ixy="1.9288894061467E-14" ixz="3.69655517006976E-13" iyy="4.84044260907388E-09" iyz="1.454864218732E-13" izz="4.34108781911687E-09"/>
    </inertial>
    <visual>
      <origin rpy="0 0 0" xyz="0 0 0"/>
      <geometry>
        <mesh filename="package://orbbec_description/meshes/gemini335_336/camera_depth_optical_frame.STL"/>
      </geometry>
      <material name="">
        <color rgba="0.501960784313725 0.250980392156863 0.250980392156863 1"/>
      </material>
    </visual>
    <collision>
      <origin rpy="0 0 0" xyz="0 0 0"/>
    </collision>
  </link>
  <joint name="camera_depth_optical_joint" type="fixed">
    <origin rpy="-1.5707963267949 0 -1.5707963267949" xyz="0.01587 -0.025 0.0125"/>
    <parent link="camera_link"/>
    <child link="camera_depth_optical_frame"/>
  </joint>
  <!-- Joint che collega la Orbbec alla testa -->
  <joint name="camera_joint" type="fixed">
    <!-- Offset della dummy camera - placeholder stilizzato in Fusion -->
    <origin rpy="0 0.099483767 0" xyz="0.057416 0.0 0.051447"/>
    <parent link="neck_pitch_link"/>
    <child link="camera_link"/>
  </joint>
  <!-- 'base_link'  to Gazebo 'world' 
<link name="world"/>

<joint name="base_link_to_world_joint" type="fixed">
  <parent link="world"/>
  <child link="base_link"/>
</joint>
-->
  <!-- Main links -->
  <link name="base_link">
    <visual>
      <origin rpy="0 0 0" xyz="0 0 0"/>
      <geometry>
        <mesh filename="file:///home/andrea/ros2_ws/install/rakuda_description/share/rakuda_description/meshes/visual/base_link.stl" scale="0.001 0.001 0.001"/>
      </geometry>
      <material name="white"/>
    </visual>
    <collision>
      <origin rpy="0 0 0" xyz="0 0 0"/>
      <geometry>
        <mesh filename="file:///home/andrea/ros2_ws/install/rakuda_description/share/rakuda_description/meshes/collision/base_link_collision.stl" scale="0.001 0.001 0.001"/>
      </geometry>
    </collision>
  </link>
  <link name="base_inertia_link">
    <inertial>
      <origin rpy="0 0 0" xyz="-0.020408922979267937 -4.8555006463835264e-05 0.05284203414197219"/>
      <mass value="1.1379124037846244"/>
      <inertia ixx="5787e-06" ixy="-4e-06" ixz="-576e-06" iyy="6743e-06" iyz="-2e-06" izz="3335e-06"/>
    </inertial>
  </link>
  <joint name="base_inertia_joint" type="fixed">
    <parent link="base_link"/>
    <child link="base_inertia_link"/>
    <origin rpy="0 0 0" xyz="0 0 0"/>
  </joint>
  <link name="waist_link">
    <inertial>
      <origin rpy="0 0 0" xyz="0.00015195021146941867 -2.820226960486473e-06 -0.004137928658236423"/>
      <mass value="0.04400005195575271"/>
      <inertia ixx="10e-06" ixy="0" ixz="0" iyy="13e-06" iyz="0" izz="17e-06"/>
    </inertial>
    <visual>
      <origin rpy="0 0 0" xyz="0.0 0.0 -0.302"/>
      <geometry>
        <mesh filename="file:///home/andrea/ros2_ws/install/rakuda_description/share/rakuda_description/meshes/visual/waist_link.stl" scale="0.001 0.001 0.001"/>
      </geometry>
      <material name="white"/>
    </visual>
    <collision>
      <origin rpy="0 0 0" xyz="0.0 0.0 -0.302"/>
      <geometry>
        <mesh filename="file:///home/andrea/ros2_ws/install/rakuda_description/share/rakuda_description/meshes/collision/waist_link_collision.stl" scale="0.001 0.001 0.001"/>
      </geometry>
    </collision>
  </link>
  <link name="torso_link">
    <inertial>
      <origin rpy="0 0 0" xyz="-0.005791332469439025 1.1532258378440722e-08 0.06653504643352193"/>
      <mass value="0.7540141547961345"/>
      <inertia ixx="1985e-06" ixy="0" ixz="-55e-06" iyy="909e-06" iyz="0" izz="1513e-06"/>
    </inertial>
    <visual>
      <origin rpy="0 0 0" xyz="-0.0 -0.0 -0.3085"/>
      <geometry>
        <mesh filename="file:///home/andrea/ros2_ws/install/rakuda_description/share/rakuda_description/meshes/visual/torso_link.stl" scale="0.001 0.001 0.001"/>
      </geometry>
      <material name="white"/>
    </visual>
    <collision>
      <origin rpy="0 0 0" xyz="-0.0 -0.0 -0.3085"/>
      <geometry>
        <mesh filename="file:///home/andrea/ros2_ws/install/rakuda_description/share/rakuda_description/meshes/collision/torso_link_collision.stl" scale="0.001 0.001 0.001"/>
      </geometry>
    </collision>
  </link>
  <link name="neck_yaw_link">
    <inertial>
      <origin rpy="0 0 0" xyz="2.8236692876973818e-15 -0.0003318177210791965 0.010126539608700469"/>
      <mass value="0.01399997346170466"/>
      <inertia ixx="5e-06" ixy="0" ixz="0" iyy="3e-06" iyz="0" izz="4e-06"/>
    </inertial>
    <visual>
      <origin rpy="0 0 0" xyz="-0.0 -0.0 -0.43405"/>
      <geometry>
        <mesh filename="file:///home/andrea/ros2_ws/install/rakuda_description/share/rakuda_description/meshes/visual/neck_yaw_link.stl" scale="0.001 0.001 0.001"/>
      </geometry>
      <material name="white"/>
    </visual>
    <collision>
      <origin rpy="0 0 0" xyz="-0.0 -0.0 -0.43405"/>
      <geometry>
        <mesh filename="file:///home/andrea/ros2_ws/install/rakuda_description/share/rakuda_description/meshes/collision/neck_yaw_link_collision.stl" scale="0.001 0.001 0.001"/>
      </geometry>
    </collision>
  </link>
  <!-- (consiglio) rinomina per non confondere i log -->
  <ros2_control name="RakudaSystem" type="system">
    <hardware>
      <plugin>dynamixel_hardware_interface/DynamixelHardware</plugin>
      <param name="port_name">/dev/ttyU2D2</param>
      <param name="baud_rate">2000000</param>
      <param name="error_timeout_ms">500</param>
      <param name="dynamixel_model_folder">/param/dxl_model</param>
      <param name="number_of_joints">17</param>
      <param name="number_of_transmissions">17</param>
      <param name="transmission_to_joint_matrix">
    1, 0, 0, 0, 0, 0, 0, 0, 0, 0, 0, 0, 0, 0, 0, 0, 0, 0, 1, 0, 0, 0, 0, 0, 0, 0, 0, 0, 0, 0, 0, 0, 0, 0, 0, 0, 1, 0, 0, 0, 0, 0, 0, 0, 0, 0, 0, 0, 0, 0, 0, 0, 0, 0, 1, 0, 0, 0, 0, 0, 0, 0, 0, 0, 0, 0, 0, 0, 0, 0, 0, 0, 1, 0, 0, 0, 0, 0, 0, 0, 0, 0, 0, 0, 0, 0, 0, 0, 0, 0, 1, 0, 0, 0, 0, 0, 0, 0, 0, 0, 0, 0, 0, 0, 0, 0, 0, 0, 1, 0, 0, 0, 0, 0, 0, 0, 0, 0, 0, 0, 0, 0, 0, 0, 0, 0, 1, 0, 0, 0, 0, 0, 0, 0, 0, 0, 0, 0, 0, 0, 0, 0, 0, 0, 1, 0, 0, 0, 0, 0, 0, 0, 0, 0, 0, 0, 0, 0, 0, 0, 0, 0, 1, 0, 0, 0, 0, 0, 0, 0, 0, 0, 0, 0, 0, 0, 0, 0, 0, 0, 1, 0, 0, 0, 0, 0, 0, 0, 0, 0, 0, 0, 0, 0, 0, 0, 0, 0, 1, 0, 0, 0, 0, 0, 0, 0, 0, 0, 0, 0, 0, 0, 0, 0, 0, 0, 1, 0, 0, 0, 0, 0, 0, 0, 0, 0, 0, 0, 0, 0, 0, 0, 0, 0, 1, 0, 0, 0, 0, 0, 0, 0, 0, 0, 0, 0, 0, 0, 0, 0, 0, 0, 1, 0, 0, 0, 0, 0, 0, 0, 0, 0, 0, 0, 0, 0, 0, 0, 0, 0, 1, 0, 0, 0, 0, 0, 0, 0, 0, 0, 0, 0, 0, 0, 0, 0, 0, 0, 1
  </param>
      <param name="joint_to_transmission_matrix">
    1, 0, 0, 0, 0, 0, 0, 0, 0, 0, 0, 0, 0, 0, 0, 0, 0, 0, 1, 0, 0, 0, 0, 0, 0, 0, 0, 0, 0, 0, 0, 0, 0, 0, 0, 0, 1, 0, 0, 0, 0, 0, 0, 0, 0, 0, 0, 0, 0, 0, 0, 0, 0, 0, 1, 0, 0, 0, 0, 0, 0, 0, 0, 0, 0, 0, 0, 0, 0, 0, 0, 0, 1, 0, 0, 0, 0, 0, 0, 0, 0, 0, 0, 0, 0, 0, 0, 0, 0, 0, 1, 0, 0, 0, 0, 0, 0, 0, 0, 0, 0, 0, 0, 0, 0, 0, 0, 0, 1, 0, 0, 0, 0, 0, 0, 0, 0, 0, 0, 0, 0, 0, 0, 0, 0, 0, 1, 0, 0, 0, 0, 0, 0, 0, 0, 0, 0, 0, 0, 0, 0, 0, 0, 0, 1, 0, 0, 0, 0, 0, 0, 0, 0, 0, 0, 0, 0, 0, 0, 0, 0, 0, 1, 0, 0, 0, 0, 0, 0, 0, 0, 0, 0, 0, 0, 0, 0, 0, 0, 0, 1, 0, 0, 0, 0, 0, 0, 0, 0, 0, 0, 0, 0, 0, 0, 0, 0, 0, 1, 0, 0, 0, 0, 0, 0, 0, 0, 0, 0, 0, 0, 0, 0, 0, 0, 0, 1, 0, 0, 0, 0, 0, 0, 0, 0, 0, 0, 0, 0, 0, 0, 0, 0, 0, 1, 0, 0, 0, 0, 0, 0, 0, 0, 0, 0, 0, 0, 0, 0, 0, 0, 0, 1, 0, 0, 0, 0, 0, 0, 0, 0, 0, 0, 0, 0, 0, 0, 0, 0, 0, 1, 0, 0, 0, 0, 0, 0, 0, 0, 0, 0, 0, 0, 0, 0, 0, 0, 0, 1
  </param>
      <param name="disable_torque_at_init">true</param>
      <param name="dynamixel_state_pub_msg_name">dynamixel_hardware_interface/dxl_state</param>
      <param name="get_dynamixel_data_srv_name">dynamixel_hardware_interface/get_dxl_data</param>
      <param name="set_dynamixel_data_srv_name">dynamixel_hardware_interface/set_dxl_data</param>
      <param name="reboot_dxl_srv_name">dynamixel_hardware_interface/reboot_dxl</param>
      <param name="set_dxl_torque_srv_name">dynamixel_hardware_interface/set_dxl_torque</param>
    </hardware>
    <joint name="waist_yaw_joint">
      <command_interface name="position"/>
      <state_interface name="position"/>
      <state_interface name="velocity"/>
      <state_interface name="effort"/>
    </joint>
    <joint name="neck_yaw_joint">
      <command_interface name="position"/>
      <state_interface name="position"/>
      <state_interface name="velocity"/>
      <state_interface name="effort"/>
    </joint>
    <joint name="neck_pitch_joint">
      <command_interface name="position"/>
      <state_interface name="position"/>
      <state_interface name="velocity"/>
      <state_interface name="effort"/>
    </joint>
    <joint name="l_arm_joint1">
      <command_interface name="position"/>
      <state_interface name="position"/>
      <state_interface name="velocity"/>
      <state_interface name="effort"/>
    </joint>
    <joint name="l_arm_joint2">
      <command_interface name="position"/>
      <state_interface name="position"/>
      <state_interface name="velocity"/>
      <state_interface name="effort"/>
    </joint>
    <joint name="l_arm_joint3">
      <command_interface name="position"/>
      <state_interface name="position"/>
      <state_interface name="velocity"/>
      <state_interface name="effort"/>
    </joint>
    <joint name="l_arm_joint4">
      <command_interface name="position"/>
      <state_interface name="position"/>
      <state_interface name="velocity"/>
      <state_interface name="effort"/>
    </joint>
    <joint name="l_arm_joint5">
      <command_interface name="position"/>
      <state_interface name="position"/>
      <state_interface name="velocity"/>
      <state_interface name="effort"/>
    </joint>
    <joint name="l_arm_joint6">
      <command_interface name="position"/>
      <state_interface name="position"/>
      <state_interface name="velocity"/>
      <state_interface name="effort"/>
    </joint>
    <joint name="l_gripper_joint">
      <command_interface name="position"/>
      <state_interface name="position"/>
      <state_interface name="velocity"/>
      <state_interface name="effort"/>
    </joint>
    <joint name="r_arm_joint1">
      <command_interface name="position"/>
      <state_interface name="position"/>
      <state_interface name="velocity"/>
      <state_interface name="effort"/>
    </joint>
    <joint name="r_arm_joint2">
      <command_interface name="position"/>
      <state_interface name="position"/>
      <state_interface name="velocity"/>
      <state_interface name="effort"/>
    </joint>
    <joint name="r_arm_joint3">
      <command_interface name="position"/>
      <state_interface name="position"/>
      <state_interface name="velocity"/>
      <state_interface name="effort"/>
    </joint>
    <joint name="r_arm_joint4">
      <command_interface name="position"/>
      <state_interface name="position"/>
      <state_interface name="velocity"/>
      <state_interface name="effort"/>
    </joint>
    <joint name="r_arm_joint5">
      <command_interface name="position"/>
      <state_interface name="position"/>
      <state_interface name="velocity"/>
      <state_interface name="effort"/>
    </joint>
    <joint name="r_arm_joint6">
      <command_interface name="position"/>
      <state_interface name="position"/>
      <state_interface name="velocity"/>
      <state_interface name="effort"/>
    </joint>
    <joint name="r_gripper_joint">
      <command_interface name="position"/>
      <state_interface name="position"/>
      <state_interface name="velocity"/>
      <state_interface name="effort"/>
    </joint>
    <!--TORSO -->
    <gpio name="dxl1">
      <param name="type">dxl</param>
      <param name="ID">1</param>
      <command_interface name="Goal Position"/>
      <state_interface name="Present Position"/>
      <state_interface name="Present Velocity"/>
      <state_interface name="Present Current"/>
      <param name="Operating Mode">3</param>
      <param name="Profile Velocity">40</param>
      <param name="Profile Acceleration">20</param>
      <param name="Position P Gain">800</param>
      <param name="Position I Gain">100</param>
      <param name="Position D Gain">100</param>
      <param name="Return Delay Time">0</param>
      <param name="Drive Mode">0</param>
    </gpio>
    <!--HEAD -->
    <gpio name="dxl2">
      <param name="type">dxl</param>
      <param name="ID">2</param>
      <command_interface name="Goal Position"/>
      <state_interface name="Present Position"/>
      <state_interface name="Present Velocity"/>
      <!--<state_interface name="Present Current"/> -->
      <param name="Operating Mode">3</param>
      <param name="Profile Velocity">360</param>
      <param name="Profile Acceleration">180</param>
      <param name="Position P Gain">800</param>
      <param name="Position I Gain">100</param>
      <param name="Position D Gain">100</param>
      <param name="Return Delay Time">0</param>
      <param name="Drive Mode">0</param>
    </gpio>
    <gpio name="dxl3">
      <param name="type">dxl</param>
      <param name="ID">3</param>
      <command_interface name="Goal Position"/>
      <state_interface name="Present Position"/>
      <state_interface name="Present Velocity"/>
      <!--<state_interface name="Present Current"/> -->
      <param name="Operating Mode">3</param>
      <param name="Profile Velocity">360</param>
      <param name="Profile Acceleration">180</param>
      <param name="Position P Gain">800</param>
      <param name="Position I Gain">100</param>
      <param name="Position D Gain">100</param>
      <param name="Return Delay Time">0</param>
      <param name="Drive Mode">1</param>
    </gpio>
    <!--LEFT ARM -->
    <gpio name="dxl11">
      <param name="type">dxl</param>
      <param name="ID">11</param>
      <command_interface name="Goal Position"/>
      <state_interface name="Present Position"/>
      <state_interface name="Present Velocity"/>
      <!--<state_interface name="Present Current"/> -->
      <param name="Operating Mode">3</param>
      <param name="Profile Velocity">80</param>
      <param name="Profile Acceleration">40</param>
      <param name="Position P Gain">800</param>
      <param name="Position I Gain">100</param>
      <param name="Position D Gain">100</param>
      <param name="Return Delay Time">0</param>
      <param name="Drive Mode">0</param>
    </gpio>
    <gpio name="dxl12">
      <param name="type">dxl</param>
      <param name="ID">12</param>
      <command_interface name="Goal Position"/>
      <state_interface name="Present Position"/>
      <state_interface name="Present Velocity"/>
      <!--<state_interface name="Present Current"/> -->
      <param name="Operating Mode">3</param>
      <param name="Profile Velocity">80</param>
      <param name="Profile Acceleration">40</param>
      <param name="Position P Gain">800</param>
      <param name="Position I Gain">100</param>
      <param name="Position D Gain">100</param>
      <param name="Return Delay Time">0</param>
      <param name="Drive Mode">1</param>
    </gpio>
    <gpio name="dxl13">
      <param name="type">dxl</param>
      <param name="ID">13</param>
      <command_interface name="Goal Position"/>
      <state_interface name="Present Position"/>
      <state_interface name="Present Velocity"/>
      <!--<state_interface name="Present Current"/> -->
      <param name="Operating Mode">3</param>
      <param name="Profile Velocity">80</param>
      <param name="Profile Acceleration">40</param>
      <param name="Position P Gain">800</param>
      <param name="Position I Gain">100</param>
      <param name="Position D Gain">100</param>
      <param name="Return Delay Time">0</param>
      <param name="Drive Mode">0</param>
    </gpio>
    <gpio name="dxl14">
      <param name="type">dxl</param>
      <param name="ID">14</param>
      <command_interface name="Goal Position"/>
      <state_interface name="Present Position"/>
      <state_interface name="Present Velocity"/>
      <!--<state_interface name="Present Current"/> -->
      <param name="Operating Mode">3</param>
      <param name="Profile Velocity">80</param>
      <param name="Profile Acceleration">40</param>
      <param name="Position P Gain">800</param>
      <param name="Position I Gain">100</param>
      <param name="Position D Gain">100</param>
      <param name="Return Delay Time">0</param>
      <param name="Drive Mode">0</param>
    </gpio>
    <gpio name="dxl15">
      <param name="type">dxl</param>
      <param name="ID">15</param>
      <command_interface name="Goal Position"/>
      <state_interface name="Present Position"/>
      <state_interface name="Present Velocity"/>
      <!--<state_interface name="Present Current"/> -->
      <param name="Operating Mode">3</param>
      <param name="Profile Velocity">80</param>
      <param name="Profile Acceleration">40</param>
      <param name="Position P Gain">800</param>
      <param name="Position I Gain">100</param>
      <param name="Position D Gain">100</param>
      <param name="Return Delay Time">0</param>
      <param name="Drive Mode">0</param>
    </gpio>
    <gpio name="dxl16">
      <param name="type">dxl</param>
      <param name="ID">16</param>
      <command_interface name="Goal Position"/>
      <state_interface name="Present Position"/>
      <state_interface name="Present Velocity"/>
      <!--<state_interface name="Present Current"/> -->
      <param name="Operating Mode">3</param>
      <param name="Profile Velocity">80</param>
      <param name="Profile Acceleration">40</param>
      <param name="Position P Gain">800</param>
      <param name="Position I Gain">100</param>
      <param name="Position D Gain">100</param>
      <param name="Return Delay Time">0</param>
      <param name="Drive Mode">0</param>
    </gpio>
    <gpio name="dxl17">
      <param name="type">dxl</param>
      <param name="ID">17</param>
      <command_interface name="Goal Position"/>
      <state_interface name="Present Position"/>
      <state_interface name="Present Velocity"/>
      <!--<state_interface name="Present Current"/> -->
      <param name="Operating Mode">3</param>
      <param name="Profile Velocity">100</param>
      <param name="Profile Acceleration">40</param>
      <param name="Position P Gain">800</param>
      <param name="Position I Gain">100</param>
      <param name="Position D Gain">100</param>
      <param name="Return Delay Time">0</param>
      <param name="Drive Mode">0</param>
    </gpio>
    <!--RIGHT ARM -->
    <gpio name="dxl21">
      <param name="type">dxl</param>
      <param name="ID">21</param>
      <command_interface name="Goal Position"/>
      <state_interface name="Present Position"/>
      <state_interface name="Present Velocity"/>
      <!--<state_interface name="Present Current"/> -->
      <param name="Operating Mode">3</param>
      <param name="Profile Velocity">80</param>
      <param name="Profile Acceleration">40</param>
      <param name="Position P Gain">800</param>
      <param name="Position I Gain">100</param>
      <param name="Position D Gain">100</param>
      <param name="Return Delay Time">0</param>
      <param name="Drive Mode">0</param>
    </gpio>
    <gpio name="dxl22">
      <param name="type">dxl</param>
      <param name="ID">22</param>
      <command_interface name="Goal Position"/>
      <state_interface name="Present Position"/>
      <state_interface name="Present Velocity"/>
      <!--<state_interface name="Present Current"/> -->
      <param name="Operating Mode">3</param>
      <param name="Profile Velocity">80</param>
      <param name="Profile Acceleration">40</param>
      <param name="Position P Gain">800</param>
      <param name="Position I Gain">100</param>
      <param name="Position D Gain">100</param>
      <param name="Return Delay Time">0</param>
      <param name="Drive Mode">1</param>
    </gpio>
    <gpio name="dxl23">
      <param name="type">dxl</param>
      <param name="ID">23</param>
      <command_interface name="Goal Position"/>
      <state_interface name="Present Position"/>
      <state_interface name="Present Velocity"/>
      <!--<state_interface name="Present Current"/> -->
      <param name="Operating Mode">3</param>
      <param name="Profile Velocity">80</param>
      <param name="Profile Acceleration">40</param>
      <param name="Position P Gain">800</param>
      <param name="Position I Gain">100</param>
      <param name="Position D Gain">100</param>
      <param name="Return Delay Time">0</param>
      <param name="Drive Mode">0</param>
    </gpio>
    <gpio name="dxl24">
      <param name="type">dxl</param>
      <param name="ID">24</param>
      <command_interface name="Goal Position"/>
      <state_interface name="Present Position"/>
      <state_interface name="Present Velocity"/>
      <!--<state_interface name="Present Current"/> -->
      <param name="Operating Mode">3</param>
      <param name="Profile Velocity">80</param>
      <param name="Profile Acceleration">40</param>
      <param name="Position P Gain">800</param>
      <param name="Position I Gain">100</param>
      <param name="Position D Gain">100</param>
      <param name="Return Delay Time">0</param>
      <param name="Drive Mode">0</param>
    </gpio>
    <gpio name="dxl25">
      <param name="type">dxl</param>
      <param name="ID">25</param>
      <command_interface name="Goal Position"/>
      <state_interface name="Present Position"/>
      <state_interface name="Present Velocity"/>
      <!--<state_interface name="Present Current"/> -->
      <param name="Operating Mode">3</param>
      <param name="Profile Velocity">80</param>
      <param name="Profile Acceleration">40</param>
      <param name="Position P Gain">800</param>
      <param name="Position I Gain">100</param>
      <param name="Position D Gain">100</param>
      <param name="Return Delay Time">0</param>
      <param name="Drive Mode">0</param>
    </gpio>
    <gpio name="dxl26">
      <param name="type">dxl</param>
      <param name="ID">26</param>
      <command_interface name="Goal Position"/>
      <state_interface name="Present Position"/>
      <state_interface name="Present Velocity"/>
      <!--<state_interface name="Present Current"/> -->
      <param name="Operating Mode">3</param>
      <param name="Profile Velocity">80</param>
      <param name="Profile Acceleration">40</param>
      <param name="Position P Gain">800</param>
      <param name="Position I Gain">100</param>
      <param name="Position D Gain">100</param>
      <param name="Return Delay Time">0</param>
      <param name="Drive Mode">0</param>
    </gpio>
    <gpio name="dxl27">
      <param name="type">dxl</param>
      <param name="ID">27</param>
      <command_interface name="Goal Position"/>
      <state_interface name="Present Position"/>
      <state_interface name="Present Velocity"/>
      <!--<state_interface name="Present Current"/> -->
      <param name="Operating Mode">3</param>
      <param name="Profile Velocity">100</param>
      <param name="Profile Acceleration">40</param>
      <param name="Position P Gain">800</param>
      <param name="Position I Gain">100</param>
      <param name="Position D Gain">100</param>
      <param name="Return Delay Time">0</param>
      <param name="Drive Mode">0</param>
    </gpio>
  </ros2_control>
  <!-- Link braccia -->
  <link name="l_link1">
    <inertial>
      <origin rpy="0 0 0" xyz="8.165392508629886e-05 0.017114007906281148 -0.01682274344663298"/>
      <mass value="0.07299177430140238"/>
      <inertia ixx="40e-06" ixy="0" ixz="0" iyy="51e-06" iyz="8e-06" izz="57e-06"/>
    </inertial>
    <visual>
      <origin rpy="0 0 0" xyz="-0.0 -0.0826 -0.3946"/>
      <geometry>
        <mesh filename="file:///home/andrea/ros2_ws/install/rakuda_description/share/rakuda_description/meshes/visual/l_link1.stl" scale="0.001 0.001 0.001"/>
      </geometry>
      <material name="white"/>
    </visual>
    <collision>
      <origin rpy="0 0 0" xyz="-0.0 -0.0826 -0.3946"/>
      <geometry>
        <mesh filename="file:///home/andrea/ros2_ws/install/rakuda_description/share/rakuda_description/meshes/collision/l_link1_collision.stl" scale="0.001 0.001 0.001"/>
      </geometry>
    </collision>
  </link>
  <link name="r_link1">
    <inertial>
      <origin rpy="0 0 0" xyz="7.710992934052517e-05 -0.017114009124667 -0.016822741627550486"/>
      <mass value="0.07299176592385347"/>
      <inertia ixx="40e-06" ixy="0" ixz="0" iyy="51e-06" iyz="-8e-06" izz="57e-06"/>
    </inertial>
    <visual>
      <origin rpy="0 0 0" xyz="-0.0 0.0826 -0.3946"/>
      <geometry>
        <mesh filename="file:///home/andrea/ros2_ws/install/rakuda_description/share/rakuda_description/meshes/visual/r_link1.stl" scale="0.001 0.001 0.001"/>
      </geometry>
      <material name="white"/>
    </visual>
    <collision>
      <origin rpy="0 0 0" xyz="-0.0 0.0826 -0.3946"/>
      <geometry>
        <mesh filename="file:///home/andrea/ros2_ws/install/rakuda_description/share/rakuda_description/meshes/collision/r_link1_collision.stl" scale="0.001 0.001 0.001"/>
      </geometry>
    </collision>
  </link>
  <link name="l_link2">
    <inertial>
      <origin rpy="0 0 0" xyz="2.482738387163369e-05 0.000396191411047242 -0.03040144548272805"/>
      <mass value="0.2900252815965671"/>
      <inertia ixx="279e-06" ixy="-1e-06" ixz="-7e-06" iyy="303e-06" iyz="-2e-06" izz="102e-06"/>
    </inertial>
    <visual>
      <origin rpy="0 0 0" xyz="-0.0 -0.1236 -0.3706"/>
      <geometry>
        <mesh filename="file:///home/andrea/ros2_ws/install/rakuda_description/share/rakuda_description/meshes/visual/l_link2.stl" scale="0.001 0.001 0.001"/>
      </geometry>
      <material name="white"/>
    </visual>
    <collision>
      <origin rpy="0 0 0" xyz="-0.0 -0.1236 -0.3706"/>
      <geometry>
        <mesh filename="file:///home/andrea/ros2_ws/install/rakuda_description/share/rakuda_description/meshes/collision/l_link2_collision.stl" scale="0.001 0.001 0.001"/>
      </geometry>
    </collision>
  </link>
  <link name="r_link2">
    <inertial>
      <origin rpy="0 0 0" xyz="2.4825375508370262e-05 -0.0003961910521785711 -0.030401438771675282"/>
      <mass value="0.2900253610511383"/>
      <inertia ixx="0.000279" ixy="1e-06" ixz="-7e-06" iyy="0.000303" iyz="2e-06" izz="0.000102"/>
    </inertial>
    <visual>
      <origin rpy="0 0 0" xyz="-0.0 0.1236 -0.3706"/>
      <geometry>
        <mesh filename="file:///home/andrea/ros2_ws/install/rakuda_description/share/rakuda_description/meshes/visual/r_link2.stl" scale="0.001 0.001 0.001"/>
      </geometry>
      <material name="white"/>
    </visual>
    <collision>
      <origin rpy="0 0 0" xyz="-0.0 0.1236 -0.3706"/>
      <geometry>
        <mesh filename="file:///home/andrea/ros2_ws/install/rakuda_description/share/rakuda_description/meshes/collision/r_link2_collision.stl" scale="0.001 0.001 0.001"/>
      </geometry>
    </collision>
  </link>
  <link name="l_link3">
    <inertial>
      <origin rpy="0 0 0" xyz="0.012816931345662554 0.0004977011098152018 -0.019558162431457693"/>
      <mass value="0.10799652996016351"/>
      <inertia ixx="25e-06" ixy="0" ixz="1e-06" iyy="43e-06" iyz="0" izz="40e-06"/>
    </inertial>
    <visual>
      <origin rpy="0 0 0" xyz="-0.012 -0.1236 -0.2884"/>
      <geometry>
        <mesh filename="file:///home/andrea/ros2_ws/install/rakuda_description/share/rakuda_description/meshes/visual/l_link3.stl" scale="0.001 0.001 0.001"/>
      </geometry>
      <material name="white"/>
    </visual>
    <collision>
      <origin rpy="0 0 0" xyz="-0.012 -0.1236 -0.2884"/>
      <geometry>
        <mesh filename="file:///home/andrea/ros2_ws/install/rakuda_description/share/rakuda_description/meshes/collision/l_link3_collision.stl" scale="0.001 0.001 0.001"/>
      </geometry>
    </collision>
  </link>
  <link name="r_link3">
    <inertial>
      <origin rpy="0 0 0" xyz="0.01281693134567282 -0.0004977011098376977 -0.019558162431519532"/>
      <mass value="0.10799652996026934"/>
      <inertia ixx="25e-06" ixy="0" ixz="1e-06" iyy="43e-06" iyz="0" izz="40e-06"/>
    </inertial>
    <visual>
      <origin rpy="0 0 0" xyz="-0.012 0.1236 -0.2884"/>
      <geometry>
        <mesh filename="file:///home/andrea/ros2_ws/install/rakuda_description/share/rakuda_description/meshes/visual/r_link3.stl" scale="0.001 0.001 0.001"/>
      </geometry>
      <material name="white"/>
    </visual>
    <collision>
      <origin rpy="0 0 0" xyz="-0.012 0.1236 -0.2884"/>
      <geometry>
        <mesh filename="file:///home/andrea/ros2_ws/install/rakuda_description/share/rakuda_description/meshes/collision/r_link3_collision.stl" scale="0.001 0.001 0.001"/>
      </geometry>
    </collision>
  </link>
  <link name="l_link4">
    <inertial>
      <origin rpy="0 0 0" xyz="-0.013529205112779118 0.001169548907603693 -0.04421637055831898"/>
      <mass value="0.10699509679197633"/>
      <inertia ixx="30e-06" ixy="1e-06" ixz="-2e-06" iyy="43e-06" iyz="0" izz="36e-06"/>
    </inertial>
    <visual>
      <origin rpy="0 0 0" xyz="-0.036 -0.1236 -0.27035"/>
      <geometry>
        <mesh filename="file:///home/andrea/ros2_ws/install/rakuda_description/share/rakuda_description/meshes/visual/l_link4.stl" scale="0.001 0.001 0.001"/>
      </geometry>
      <material name="white"/>
    </visual>
    <collision>
      <origin rpy="0 0 0" xyz="-0.036 -0.1236 -0.27035"/>
      <geometry>
        <mesh filename="file:///home/andrea/ros2_ws/install/rakuda_description/share/rakuda_description/meshes/collision/l_link4_collision.stl" scale="0.001 0.001 0.001"/>
      </geometry>
    </collision>
  </link>
  <link name="r_link4">
    <inertial>
      <origin rpy="0 0 0" xyz="-0.013529205589267821 -0.0011695493323802958 -0.04421637085671126"/>
      <mass value="0.10699509934326328"/>
      <inertia ixx="30e-06" ixy="-1e-06" ixz="-2e-06" iyy="43e-06" iyz="0" izz="36e-06"/>
    </inertial>
    <visual>
      <origin rpy="0 0 0" xyz="-0.036 0.1236 -0.27035"/>
      <geometry>
        <mesh filename="file:///home/andrea/ros2_ws/install/rakuda_description/share/rakuda_description/meshes/visual/r_link4.stl" scale="0.001 0.001 0.001"/>
      </geometry>
      <material name="white"/>
    </visual>
    <collision>
      <origin rpy="0 0 0" xyz="-0.036 0.1236 -0.27035"/>
      <geometry>
        <mesh filename="file:///home/andrea/ros2_ws/install/rakuda_description/share/rakuda_description/meshes/collision/r_link4_collision.stl" scale="0.001 0.001 0.001"/>
      </geometry>
    </collision>
  </link>
  <link name="l_link5">
    <inertial>
      <origin rpy="0 0 0" xyz="-0.00010745262237027431 0.0004983218880769968 -0.02809682280934908"/>
      <mass value="0.10899653712889695"/>
      <inertia ixx="40e-06" ixy="0" ixz="0" iyy="44e-06" iyz="0" izz="26e-06"/>
    </inertial>
    <visual>
      <origin rpy="0 0 0" xyz="-0.036 -0.1236 -0.2049"/>
      <geometry>
        <mesh filename="file:///home/andrea/ros2_ws/install/rakuda_description/share/rakuda_description/meshes/visual/l_link5.stl" scale="0.001 0.001 0.001"/>
      </geometry>
      <material name="white"/>
    </visual>
    <collision>
      <origin rpy="0 0 0" xyz="-0.036 -0.1236 -0.2049"/>
      <geometry>
        <mesh filename="file:///home/andrea/ros2_ws/install/rakuda_description/share/rakuda_description/meshes/collision/l_link5_collision.stl" scale="0.001 0.001 0.001"/>
      </geometry>
    </collision>
  </link>
  <link name="r_link5">
    <inertial>
      <origin rpy="0 0 0" xyz="-0.00010749374651377458 -0.00049827898943898 -0.02809678801928564"/>
      <mass value="0.10899673027569862"/>
      <inertia ixx="40e-06" ixy="0" ixz="0" iyy="44e-06" iyz="0" izz="26e-06"/>
    </inertial>
    <visual>
      <origin rpy="0 0 0" xyz="-0.036 0.1236 -0.2049"/>
      <geometry>
        <mesh filename="file:///home/andrea/ros2_ws/install/rakuda_description/share/rakuda_description/meshes/visual/r_link5.stl" scale="0.001 0.001 0.001"/>
      </geometry>
      <material name="white"/>
    </visual>
    <collision>
      <origin rpy="0 0 0" xyz="-0.036 0.1236 -0.2049"/>
      <geometry>
        <mesh filename="file:///home/andrea/ros2_ws/install/rakuda_description/share/rakuda_description/meshes/collision/r_link5_collision.stl" scale="0.001 0.001 0.001"/>
      </geometry>
    </collision>
  </link>
  <link name="r_link6">
    <inertial>
      <origin rpy="0 0 0" xyz="0.0004978784895699889 -0.003188942119494928 -0.03994743914308038"/>
      <mass value="0.07399870180333049"/>
      <inertia ixx="23e-06" ixy="0" ixz="0" iyy="17e-06" iyz="0" izz="22e-06"/>
    </inertial>
    <visual>
      <origin rpy="0 0 0" xyz="-0.036 0.1236 -0.16585"/>
      <geometry>
        <mesh filename="file:///home/andrea/ros2_ws/install/rakuda_description/share/rakuda_description/meshes/visual/r_link6.stl" scale="0.001 0.001 0.001"/>
      </geometry>
      <material name="white"/>
    </visual>
    <collision>
      <origin rpy="0 0 0" xyz="-0.036 0.1236 -0.16585"/>
      <geometry>
        <mesh filename="file:///home/andrea/ros2_ws/install/rakuda_description/share/rakuda_description/meshes/collision/r_link6_collision.stl" scale="0.001 0.001 0.001"/>
      </geometry>
    </collision>
  </link>
  <link name="l_link6">
    <inertial>
      <origin rpy="0 0 0" xyz="0.000497878489597231 0.00318894211964936 -0.03994743914314852"/>
      <mass value="0.07399870180299768"/>
      <inertia ixx="23e-06" ixy="0" ixz="0" iyy="17e-06" iyz="0" izz="22e-06"/>
    </inertial>
    <visual>
      <origin rpy="0 0 0" xyz="-0.036 -0.1236 -0.16585"/>
      <geometry>
        <mesh filename="file:///home/andrea/ros2_ws/install/rakuda_description/share/rakuda_description/meshes/visual/l_link6.stl" scale="0.001 0.001 0.001"/>
      </geometry>
      <material name="white"/>
    </visual>
    <collision>
      <origin rpy="0 0 0" xyz="-0.036 -0.1236 -0.16585"/>
      <geometry>
        <mesh filename="file:///home/andrea/ros2_ws/install/rakuda_description/share/rakuda_description/meshes/collision/l_link6_collision.stl" scale="0.001 0.001 0.001"/>
      </geometry>
    </collision>
  </link>
  <link name="r_gripper_a">
    <inertial>
      <origin rpy="0 0 0" xyz="-8.852479904033345e-05 -0.003089211052713342 -0.02999149965192692"/>
      <mass value="0.017998423512260126"/>
      <inertia ixx="6e-06" ixy="0" ixz="0" iyy="10e-06" iyz="0" izz="5e-06"/>
    </inertial>
    <visual>
      <origin rpy="0 0 0" xyz="-0.036 0.1396 -0.1236"/>
      <geometry>
        <mesh filename="file:///home/andrea/ros2_ws/install/rakuda_description/share/rakuda_description/meshes/visual/r_gripper_a.stl" scale="0.001 0.001 0.001"/>
      </geometry>
      <material name="white"/>
    </visual>
    <collision>
      <origin rpy="0 0 0" xyz="-0.036 0.1396 -0.1236"/>
      <geometry>
        <mesh filename="file:///home/andrea/ros2_ws/install/rakuda_description/share/rakuda_description/meshes/collision/r_gripper_a_collision.stl" scale="0.001 0.001 0.001"/>
      </geometry>
    </collision>
  </link>
  <link name="r_gripper_b">
    <inertial>
      <origin rpy="0 0 0" xyz="-8.852479904033345e-05 0.003104658168288782 -0.030279426009768864"/>
      <mass value="0.018999892317782645"/>
      <inertia ixx="6e-06" ixy="0" ixz="0" iyy="10e-06" iyz="0" izz="5e-06"/>
    </inertial>
    <visual>
      <origin rpy="0 0 0" xyz="-0.036 0.1156 -0.12355"/>
      <geometry>
        <mesh filename="file:///home/andrea/ros2_ws/install/rakuda_description/share/rakuda_description/meshes/visual/r_gripper_b.stl" scale="0.001 0.001 0.001"/>
      </geometry>
      <material name="white"/>
    </visual>
    <collision>
      <origin rpy="0 0 0" xyz="-0.036 0.1156 -0.12355"/>
      <geometry>
        <mesh filename="file:///home/andrea/ros2_ws/install/rakuda_description/share/rakuda_description/meshes/collision/r_gripper_b_collision.stl" scale="0.001 0.001 0.001"/>
      </geometry>
    </collision>
  </link>
  <link name="l_gripper_a">
    <inertial>
      <origin rpy="0 0 0" xyz="-8.920360655783471e-05 0.003089714518583392 -0.029990508331487045"/>
      <mass value="0.017997801931831644"/>
      <inertia ixx="6e-06" ixy="0" ixz="0" iyy="10e-06" iyz="0" izz="5e-06"/>
    </inertial>
    <visual>
      <origin rpy="0 0 0" xyz="-0.036 -0.1396 -0.1236"/>
      <geometry>
        <mesh filename="file:///home/andrea/ros2_ws/install/rakuda_description/share/rakuda_description/meshes/visual/l_gripper_a.stl" scale="0.001 0.001 0.001"/>
      </geometry>
      <material name="white"/>
    </visual>
    <collision>
      <origin rpy="0 0 0" xyz="-0.036 -0.1396 -0.1236"/>
      <geometry>
        <mesh filename="file:///home/andrea/ros2_ws/install/rakuda_description/share/rakuda_description/meshes/collision/l_gripper_a_collision.stl" scale="0.001 0.001 0.001"/>
      </geometry>
    </collision>
  </link>
  <link name="l_gripper_b">
    <inertial>
      <origin rpy="0 0 0" xyz="-8.920360655783471e-05 -0.0031035251440137968 -0.030280490115251982"/>
      <mass value="0.019000550359800868"/>
      <inertia ixx="6e-06" ixy="0" ixz="0" iyy="10e-06" iyz="0" izz="5e-06"/>
    </inertial>
    <visual>
      <origin rpy="0 0 0" xyz="-0.036 -0.1156 -0.12355"/>
      <geometry>
        <mesh filename="file:///home/andrea/ros2_ws/install/rakuda_description/share/rakuda_description/meshes/visual/l_gripper_b.stl" scale="0.001 0.001 0.001"/>
      </geometry>
      <material name="white"/>
    </visual>
    <collision>
      <origin rpy="0 0 0" xyz="-0.036 -0.1156 -0.12355"/>
      <geometry>
        <mesh filename="file:///home/andrea/ros2_ws/install/rakuda_description/share/rakuda_description/meshes/collision/l_gripper_b_collision.stl" scale="0.001 0.001 0.001"/>
      </geometry>
    </collision>
  </link>
  <!-- Joints -->
  <joint name="base_waist_joint" type="fixed">
    <origin rpy="0 0 0" xyz="0.0 0.0 0.306"/>
    <parent link="base_link"/>
    <child link="waist_link"/>
  </joint>
  <joint name="waist_yaw_joint" type="revolute">
    <origin rpy="0 0 0" xyz="0.0 0.0 0.0065"/>
    <parent link="waist_link"/>
    <child link="torso_link"/>
    <axis xyz="0.0 0.0 1.0"/>
    <limit effort="100.0" lower="-1.396263" upper="1.396263" velocity="4.8"/>
    <dynamics damping="1.0e-6" friction="0.8"/>
  </joint>
  <joint name="neck_yaw_joint" type="revolute">
    <origin rpy="0 0 0" xyz="0.0 0.0 0.12555"/>
    <parent link="torso_link"/>
    <child link="neck_yaw_link"/>
    <axis xyz="0.0 0.0 1.0"/>
    <!-- Sciurus17 limit upper="1.22173" lower="-1.22173" effort="100.0" velocity="4.8"/ -->
    <limit effort="100.0" lower="-0.660" upper="0.660" velocity="4.8"/>
    <dynamics damping="1.0e-6" friction="0.8"/>
  </joint>
  <joint name="l_arm_joint1" type="revolute">
    <origin rpy="0 0 0" xyz="0.0 0.0826 0.0861"/>
    <parent link="torso_link"/>
    <child link="l_link1"/>
    <axis xyz="0.0 1.0 0.0"/>
    <limit effort="100.0" lower="-2.96706" upper="0.0" velocity="4.8"/>
    <dynamics damping="1.0e-6" friction="0.8"/>
  </joint>
  <joint name="r_arm_joint1" type="revolute">
    <origin rpy="0 0 0" xyz="0.0 -0.0826 0.0861"/>
    <parent link="torso_link"/>
    <child link="r_link1"/>
    <axis xyz="0.0 -1.0 0.0"/>
    <limit effort="100.0" lower="0.0" upper="2.96706" velocity="4.8"/>
    <dynamics damping="1.0e-6" friction="0.8"/>
  </joint>
  <joint name="l_arm_joint2" type="revolute">
    <origin rpy="0 0 0" xyz="0.0 0.041 -0.024"/>
    <parent link="l_link1"/>
    <child link="l_link2"/>
    <axis xyz="1.0 0.0 0.0"/>
    <limit effort="100.0" lower="-0.0" upper="1.570796" velocity="4.8"/>
    <dynamics damping="1.0e-6" friction="0.8"/>
  </joint>
  <joint name="r_arm_joint2" type="revolute">
    <origin rpy="0 0 0" xyz="0.0 -0.041 -0.024"/>
    <parent link="r_link1"/>
    <child link="r_link2"/>
    <axis xyz="1.0 0.0 0.0"/>
    <limit effort="100.0" lower="-1.570796" upper="0.0" velocity="4.8"/>
    <dynamics damping="1.0e-6" friction="0.8"/>
  </joint>
  <joint name="l_arm_joint3" type="revolute">
    <origin rpy="0 0 0" xyz="0.012 0.0 -0.0822"/>
    <parent link="l_link2"/>
    <child link="l_link3"/>
    <axis xyz="0.0 0.0 -1.0"/>
    <limit effort="100.0" lower="-1.396263" upper="1.396263" velocity="4.8"/>
    <dynamics damping="1.0e-6" friction="0.8"/>
  </joint>
  <joint name="r_arm_joint3" type="revolute">
    <origin rpy="0 0 0" xyz="0.012 0.0 -0.0822"/>
    <parent link="r_link2"/>
    <child link="r_link3"/>
    <axis xyz="0.0 0.0 -1.0"/>
    <limit effort="100.0" lower="-1.396263" upper="1.396263" velocity="4.8"/>
    <dynamics damping="1.0e-6" friction="0.8"/>
  </joint>
  <joint name="l_arm_joint4" type="revolute">
    <origin rpy="0 0 0" xyz="0.024 0.0 -0.01805"/>
    <parent link="l_link3"/>
    <child link="l_link4"/>
    <axis xyz="0.0 1.0 0.0"/>
    <limit effort="100.0" lower="-2.356194" upper="0.174533" velocity="4.8"/>
    <dynamics damping="1.0e-6" friction="0.8"/>
  </joint>
  <joint name="r_arm_joint4" type="revolute">
    <origin rpy="0 0 0" xyz="0.024 0.0 -0.01805"/>
    <parent link="r_link3"/>
    <child link="r_link4"/>
    <axis xyz="0.0 -1.0 0.0"/>
    <limit effort="100.0" lower="-0.174533" upper="2.356194" velocity="4.8"/>
    <dynamics damping="1.0e-6" friction="0.8"/>
  </joint>
  <joint name="l_arm_joint5" type="revolute">
    <origin rpy="0 0 0" xyz="0.0 0.0 -0.06545"/>
    <parent link="l_link4"/>
    <child link="l_link5"/>
    <axis xyz="0.0 0.0 -1.0"/>
    <limit effort="100.0" lower="-1.570796" upper="1.570796" velocity="4.8"/>
    <dynamics damping="1.0e-6" friction="0.8"/>
  </joint>
  <joint name="r_arm_joint5" type="revolute">
    <origin rpy="0 0 0" xyz="0.0 0.0 -0.06545"/>
    <parent link="r_link4"/>
    <child link="r_link5"/>
    <axis xyz="0.0 0.0 -1.0"/>
    <limit effort="100.0" lower="-1.570796" upper="1.570796" velocity="4.8"/>
    <dynamics damping="1.0e-6" friction="0.8"/>
  </joint>
  <joint name="r_arm_joint6" type="revolute">
    <origin rpy="0 0 0" xyz="0.0 0.0 -0.03905"/>
    <parent link="r_link5"/>
    <child link="r_link6"/>
    <axis xyz="0.0 -1.0 0.0"/>
    <limit effort="100.0" lower="-1.396263" upper="1.396263" velocity="4.8"/>
    <dynamics damping="1.0e-6" friction="0.8"/>
  </joint>
  <joint name="l_arm_joint6" type="revolute">
    <origin rpy="0 0 0" xyz="0.0 0.0 -0.03905"/>
    <parent link="l_link5"/>
    <child link="l_link6"/>
    <axis xyz="0.0 1.0 0.0"/>
    <limit effort="100.0" lower="-1.396263" upper="1.396263" velocity="4.8"/>
    <dynamics damping="1.0e-6" friction="0.8"/>
  </joint>
  <joint name="r_gripper_joint" type="revolute">
    <origin rpy="0 0 0" xyz="0.0 -0.016 -0.04225"/>
    <parent link="r_link6"/>
    <child link="r_gripper_a"/>
    <axis xyz="1.0 0.0 0.0"/>
    <limit effort="100.0" lower="-1.22173" upper="0.0" velocity="4.8"/>
    <dynamics damping="1.0e-6" friction="0.8"/>
  </joint>
  <joint name="r_gripper_mimic_joint" type="revolute">
    <origin rpy="0 0 0" xyz="0.0 0.008 -0.0423"/>
    <limit effort="10" lower="-1.0" upper="0.01" velocity="1.0"/>
    <parent link="r_link6"/>
    <child link="r_gripper_b"/>
    <axis xyz="1.0 0.0 0.0"/>
    <mimic joint="r_gripper_joint" multiplier="-1.0" offset="0.0"/>
  </joint>
  <joint name="l_gripper_joint" type="revolute">
    <origin rpy="0 0 0" xyz="0.0 0.016 -0.04225"/>
    <parent link="l_link6"/>
    <child link="l_gripper_a"/>
    <axis xyz="1.0 0.0 0.0"/>
    <limit effort="100.0" lower="0.0" upper="1.22173" velocity="4.8"/>
    <dynamics damping="1.0e-6" friction="0.8"/>
  </joint>
  <joint name="l_gripper_mimic_joint" type="revolute">
    <origin rpy="0 0 0" xyz="0.0 -0.008 -0.0423"/>
    <limit effort="10" lower="-0.01" upper="1.0" velocity="1.0"/>
    <parent link="l_link6"/>
    <child link="l_gripper_b"/>
    <axis xyz="1.0 0.0 0.0"/>
    <mimic joint="l_gripper_joint" multiplier="-1.0" offset="0.0"/>
  </joint>
</robot>
